Workbook

Sheet Transactions
A1: transaction_id | B1: branch_code | C1: date_of_sale | D1: staff_id | E1: product_category | F1: product_name | G1: quantity | H1: unit_price | I1: discount_applied | J1: payment_type | K1: customer_type | L1: total_sale | M1: returned
A2: 5453 | B2: BR02 | C2: 24/1/2024 | D2: S006 | E2: Electronics | F2: Bluetooth Speaker | G2: 5 | H2: N/A | I2: 0% | J2: Card | K2: RETURNING | M2: no
A3: 5302 | B3: BR01 | C3: 18-Jan-24 | D3: S002 | E3: Home & Kitchen | F3: Storage Containers | H3: 10605.57 | I3: None | J3: card | K3: RETURNING | M3: Y
A4: 5026 | B4: BR02 | C4: 9/15/2024 | D4: S005 | E4: Groceries | F4: Spaghetti Pack | H4: ₦8,416.54 | I4: 0% | J4: Card | K4: New | M4: Yes
A5: 5001 | B5: BR02 | C5: 5/8/2024 | D5: S002 | E5: Electronics | F5: HDMI Cable | G5: 5 | H5: N/A | I5: 15% | J5: card | K5: new | M5: Yes
A6: 5380 | B6: BR01 | C6: 22-May-24 | D6: S002 | E6: Home & Kitchen | F6: Blender | G6: 1 | H6: N/A | I6: None | J6: Cash | K6: returning
A7: 5214 | B7: BRXX | C7: 26/8/2024 | D7: S003 | E7: Home & Kitchen | F7: Cutlery Set | H7: 33,815.79 | I7: 5% | J7: Cash | K7: returning | M7: Yes
A8: 5410 | B8: BR04 | C8: 16/8/2024 | D8: S007 | E8: Groceries | F8: Cooking Oil (1L) | G8: 5 | H8: 23072.48 | I8: 0% | J8: Transfer | K8: NEW | M8: no
A9: 5350 | B9: br01 | C9: May 3, 2024 | D9: S006 | E9: Personal Care | F9: Toothpaste | G9: 5 | H9: 32,386.21 | I9: 0% | J9: card | K9: new | M9: N
A10: 5445 | B10: BR05 | C10: 2024-03-06 | D10: S007 | E10: Home & Kitchen | F10: Cutlery Set | G10: 1 | H10: 1,321.59 | I10: 10% | J10: Card | K10: Returning | M10: yes
A11: 5227 | B11: BR05 | C11: 4/6/2024 | D11: S001 | E11: Personal Care | F11: Deodorant | H11: N/A | I11: None | J11: transfer | K11: new | M11: No
A12: 5478 | B12: br03 | C12: 15-Apr-24 | D12: S003 | E12: Electronics | F12: Phone Charger | H12: 26,958.25 | I12: 10% | J12: transfer | K12: Returning | M12: N
A13: 5439 | B13: BR02 | C13: May 8, 2024 | D13: S004 | E13: Personal Care | F13: Toothpaste | G13: 3 | H13: N/A | I13: 5% | J13: CASH | K13: New | M13: no
A14: 5058 | B14: BR01 | C14: September 19, 2024 | D14: S099 | E14: Home & Kitchen | F14: Blender | G14: 3 | H14: N/A | I14: N/A | J14: Cash | K14: New | M14: No
A15: 5384 | B15: BR05 | C15: 6-Apr-24 | D15: S004 | E15: Home & Kitchen | F15: Storage Containers | G15: 2 | H15: 17169.84 | I15: 15% | J15: Transfer | K15: returning | M15: no
A16: 5101 | B16: BR05 | C16: 2024-09-14 | D16: S004 | E16: Personal Care | F16: Deodorant | G16: 3 | H16: 25154.23 | I16: 0% | J16: transfer | K16: Returning | M16: No
A17: 5176 | B17: BR03 | C17: 22-Mar-24 | D17: S100 | E17: Groceries | F17: Tomato Paste | G17: 1 | H17: N/A | I17: 5% | J17: Transfer | K17: Returning | M17: no
A18: 5310 | B18: BR04 | C18: 2024-06-20 | D18: S003 | E18: Groceries | F18: Cooking Oil (1L) | H18: N/A | I18: 10% | J18: CASH | K18: RETURNING | M18: no
A19: 5167 | B19: BR03 | C19: March 31, 2024 | D19: S007 | E19: Groceries | F19: Spaghetti Pack | G19: 1 | H19: 23400.68 | I19: 10% | J19: transfer | K19: New | M19: N
A20: 5217 | B20: BR05 | C20: 26/9/2024 | D20: S003 | E20: Groceries | F20: Tomato Paste | G20: 4 | H20: ₦5,589.59 | I20: None | J20: Cash | K20: RETURNING | M20: Y
A21: 5007 | B21: BR02 | C21: 2024-07-31 | D21: S008 | E21: Electronics | F21: Power Bank | G21: 5 | H21: N/A | J21: Card | K21: NEW | M21: N
A22: 5363 | B22: BR05 | C22: September 18, 2024 | D22: S003 | E22: Home & Kitchen | F22: Kettle | G22: 4 | H22: 37,413.70 | I22: 0% | J22: cash | K22: RETURNING
A23: 5271 | B23: br03 | C23: January 29, 2024 | D23: S004 | E23: Personal Care | F23: Soap Bar | G23: 5 | H23: N/A | I23: 10% | J23: Card | K23: Returning | M23: Y
A24: 5235 | B24: BR03 | C24: 3/29/2024 | D24: S008 | E24: Electronics | F24: HDMI Cable | G24: 1 | H24: 42,907.41 | I24: 5% | J24: Card | K24: New | M24: no
A25: 5116 | B25: br02 | C25: 22/7/2024 | D25: S006 | E25: Groceries | F25: Cooking Oil (1L) | G25: 1 | H25: N/A | I25: 15% | J25: card | K25: Returning | M25: Y
A26: 5353 | B26: BR05 | C26: 18/4/2024 | D26: S008 | E26: Home & Kitchen | F26: Cutlery Set | G26: 1 | H26: N/A | I26: 10% | J26: cash | K26: Returning
A27: 5338 | B27: BR05 | C27: February 21, 2024 | D27: S003 | E27: Groceries | F27: Cooking Oil (1L) | H27: N/A | I27: 10% | J27: Cash | K27: RETURNING | M27: no
A28: 5343 | B28: BR02 | C28: September 22, 2024 | D28: S006 | E28: Electronics | F28: HDMI Cable | G28: 3 | H28: N/A | I28: None | J28: Card | K28: new | M28: No
A29: 5372 | B29: BR01 | C29: 8/24/2024 | D29: S008 | E29: Home & Kitchen | F29: Kettle | G29: 4 | H29: N/A | I29: 5% | J29: Card | K29: returning | M29: yes
A30: 5224 | B30: BR01 | C30: February 1, 2024 | D30: S002 | E30: Personal Care | F30: Soap Bar | G30: 1 | H30: 30,043.06 | I30: N/A | J30: Card | K30: RETURNING
A31: 5205 | B31: BR04 | C31: 2024-01-22 | D31: S008 | E31: Electronics | F31: Power Bank | G31: 3 | H31: ₦27,994.84 | I31: None | J31: transfer | K31: Returning | M31: No
A32: 5305 | B32: BRXX | C32: April 19, 2024 | D32: S002 | E32: Personal Care | F32: Shampoo | G32: 2 | H32: 22,968.48 | I32: N/A | J32: transfer | K32: new | M32: Y
A33: 5210 | B33: br02 | C33: 2024-01-27 | D33: S001 | E33: Groceries | F33: Sugar (1kg) | G33: 3 | H33: 4354.34 | I33: N/A | J33: Transfer | K33: returning | M33: no
A34: 5008 | B34: BR04 | C34: 7/8/2024 | D34: S003 | E34: Groceries | F34: Cooking Oil (1L) | G34: 1 | H34: 22080.84 | I34: 0% | J34: Card | K34: new | M34: no
A35: 5355 | B35: BR05 | C35: 7/6/2024 | D35: S007 | E35: Personal Care | F35: Body Lotion | G35: 5 | H35: ₦25,569.20 | I35: N/A | J35: CASH | K35: Returning | M35: Yes
A36: 5431 | B36: BR05 | C36: 2024-03-01 | D36: S003 | E36: Electronics | F36: HDMI Cable | G36: 2 | H36: ₦36,302.69 | I36: None | J36: Cash | K36: Returning | M36: Yes
A37: 5373 | B37: BR05 | C37: 2024-03-08 | D37: S002 | E37: Personal Care | F37: Deodorant | G37: 1 | H37: 12,020.08 | J37: Cash | K37: Returning
A38: 5402 | B38: BR05 | C38: 2024-02-20 | D38: S006 | E38: Groceries | F38: Cooking Oil (1L) | G38: 1 | H38: 30457.19 | J38: Card | K38: NEW | M38: No
A39: 5394 | B39: BR09 | C39: 3-Feb-24 | D39: S008 | E39: Home & Kitchen | F39: Blender | G39: 5 | H39: N/A | I39: None | J39: cash | K39: Returning | M39: Y
A40: 5103 | B40: br04 | C40: February 12, 2024 | D40: S001 | E40: Groceries | F40: Tomato Paste | H40: N/A | I40: N/A | J40: CARD | K40: RETURNING | M40: N
...

Sheet Cleaned_Transactions
A1: Transaction_Id | B1: Branch_Code | C1: Branch_Name | D1: Date_of_Sale | E1: Staff_Id | F1: Staff_Name | G1: Product_Category | H1: Product_Name | I1: Quantity | J1: Unit_Price | K1: Discount_Applied | L1: Payment_Method | M1: Customer_Type | N1: Total_Sale | O1: Returned
A2: 5453 | B2: BR02 | C2: =IFERROR(VLOOKUP(B2,Branches!A:B, 2, FALSE), B2&"(NOT FOUND)") -> Wuse Branch | D2: 45315 | E2: S006 | F2: =IFERROR(VLOOKUP(E2, Staff!A:B, 2, FALSE), E2&" (NOT FOUND)") -> Ibrahim Sani | G2: Electronics | H2: Bluetooth Speaker | I2: 5 | K2: 0 | L2: Card | M2: Returning | N2: =IF(OR(I2="",J2=""),"",IF(OR(K2="", K2=0), I2*J2, (I2*J2)-(K2/100)*I2*J2)) | O2: NO
A3: 5302 | B3: BR01 | C3: =IFERROR(VLOOKUP(B3,Branches!A:B, 2, FALSE), B3&"(NOT FOUND)") -> Lekki Branch | D3: 45309 | E3: S002 | F3: =IFERROR(VLOOKUP(E3, Staff!A:B, 2, FALSE), E3&" (NOT FOUND)") -> Tobi Adewale | G3: Home & Kitchen | H3: Storage Containers | J3: 10605.57 | L3: Card | M3: Returning | N3: =IF(OR(I3="",J3=""),"",IF(OR(K3="", K3=0), I3*J3, (I3*J3)-(K3/100)*I3*J3)) | O3: YES
A4: 5026 | B4: BR02 | C4: =IFERROR(VLOOKUP(B4,Branches!A:B, 2, FALSE), B4&"(NOT FOUND)") -> Wuse Branch | D4: 45550 | E4: S005 | F4: =IFERROR(VLOOKUP(E4, Staff!A:B, 2, FALSE), E4&" (NOT FOUND)") -> Funke Ajayi | G4: Groceries | H4: Spaghetti Pack | J4: 8416.54 | K4: 0 | L4: Card | M4: New | N4: =IF(OR(I4="",J4=""),"",IF(OR(K4="", K4=0), I4*J4, (I4*J4)-(K4/100)*I4*J4)) | O4: YES
A5: 5001 | B5: BR02 | C5: =IFERROR(VLOOKUP(B5,Branches!A:B, 2, FALSE), B5&"(NOT FOUND)") -> Wuse Branch | D5: 45509 | E5: S002 | F5: =IFERROR(VLOOKUP(E5, Staff!A:B, 2, FALSE), E5&" (NOT FOUND)") -> Tobi Adewale | G5: Electronics | H5: HDMI Cable | I5: 5 | K5: 15 | L5: Card | M5: New | N5: =IF(OR(I5="",J5=""),"",IF(OR(K5="", K5=0), I5*J5, (I5*J5)-(K5/100)*I5*J5)) | O5: YES
A6: 5380 | B6: BR01 | C6: =IFERROR(VLOOKUP(B6,Branches!A:B, 2, FALSE), B6&"(NOT FOUND)") -> Lekki Branch | D6: 45434 | E6: S002 | F6: =IFERROR(VLOOKUP(E6, Staff!A:B, 2, FALSE), E6&" (NOT FOUND)") -> Tobi Adewale | G6: Home & Kitchen | H6: Blender | I6: 1 | L6: Cash | M6: Returning | N6: =IF(OR(I6="",J6=""),"",IF(OR(K6="", K6=0), I6*J6, (I6*J6)-(K6/100)*I6*J6)) | Q6: =IFERROR(VALUE(SUBSTITUTE(#REF!,"₦","")), "")
A7: 5214 | B7: BRXX | C7: =IFERROR(VLOOKUP(B7,Branches!A:B, 2, FALSE), B7&"(NOT FOUND)") -> BRXX(NOT FOUND) | D7: 45530 | E7: S003 | F7: =IFERROR(VLOOKUP(E7, Staff!A:B, 2, FALSE), E7&" (NOT FOUND)") -> Halima Yusuf | G7: Home & Kitchen | H7: Cutlery Set | J7: 33815.79 | K7: 5 | L7: Cash | M7: Returning | N7: =IF(OR(I7="",J7=""),"",IF(OR(K7="", K7=0), I7*J7, (I7*J7)-(K7/100)*I7*J7)) | O7: YES
A8: 5410 | B8: BR04 | C8: =IFERROR(VLOOKUP(B8,Branches!A:B, 2, FALSE), B8&"(NOT FOUND)") -> Sabon Gari Branch | D8: 45520 | E8: S007 | F8: =IFERROR(VLOOKUP(E8, Staff!A:B, 2, FALSE), E8&" (NOT FOUND)") -> Kelechi Umeh | G8: Groceries | H8: Cooking Oil (1L) | I8: 5 | J8: 23072.48 | K8: 0 | L8: Transfer | M8: New | N8: =IF(OR(I8="",J8=""),"",IF(OR(K8="", K8=0), I8*J8, (I8*J8)-(K8/100)*I8*J8)) -> 115362.4 | O8: NO | Q8: =IFERROR(VALUE(SUBSTITUTE(#REF!,"₦","")), "")
A9: 5350 | B9: BR01 | C9: =IFERROR(VLOOKUP(B9,Branches!A:B, 2, FALSE), B9&"(NOT FOUND)") -> Lekki Branch | D9: 45415 | E9: S006 | F9: =IFERROR(VLOOKUP(E9, Staff!A:B, 2, FALSE), E9&" (NOT FOUND)") -> Ibrahim Sani | G9: Personal Care | H9: Toothpaste | I9: 5 | J9: 32386.21 | K9: 0 | L9: Card | M9: New | N9: =IF(OR(I9="",J9=""),"",IF(OR(K9="", K9=0), I9*J9, (I9*J9)-(K9/100)*I9*J9)) -> 161931.05 | O9: NO | Q9: =IFERROR(VALUE(SUBSTITUTE(#REF!,"₦","")), "")
A10: 5445 | B10: BR05 | C10: =IFERROR(VLOOKUP(B10,Branches!A:B, 2, FALSE), B10&"(NOT FOUND)") -> Bodija Branch | D10: 45357 | E10: S007 | F10: =IFERROR(VLOOKUP(E10, Staff!A:B, 2, FALSE), E10&" (NOT FOUND)") -> Kelechi Umeh | G10: Home & Kitchen | H10: Cutlery Set | I10: 1 | J10: 1321.59 | K10: 10 | L10: Card | M10: Returning | N10: =IF(OR(I10="",J10=""),"",IF(OR(K10="", K10=0), I10*J10, (I10*J10)-(K10/100)*I10*J10)) -> 1189.431 | O10: YES
A11: 5227 | B11: BR05 | C11: =IFERROR(VLOOKUP(B11,Branches!A:B, 2, FALSE), B11&"(NOT FOUND)") -> Bodija Branch | D11: 45447 | E11: S001 | F11: =IFERROR(VLOOKUP(E11, Staff!A:B, 2, FALSE), E11&" (NOT FOUND)") -> Chika Nwankwo | G11: Personal Care | H11: Deodorant | L11: Transfer | M11: New | N11: =IF(OR(I11="",J11=""),"",IF(OR(K11="", K11=0), I11*J11, (I11*J11)-(K11/100)*I11*J11)) | O11: NO
A12: 5478 | B12: BR03 | C12: =IFERROR(VLOOKUP(B12,Branches!A:B, 2, FALSE), B12&"(NOT FOUND)") -> GRA Branch | D12: 45397 | E12: S003 | F12: =IFERROR(VLOOKUP(E12, Staff!A:B, 2, FALSE), E12&" (NOT FOUND)") -> Halima Yusuf | G12: Electronics | H12: Phone Charger | J12: 26958.25 | K12: 10 | L12: Transfer | M12: Returning | N12: =IF(OR(I12="",J12=""),"",IF(OR(K12="", K12=0), I12*J12, (I12*J12)-(K12/100)*I12*J12)) | O12: NO
A13: 5439 | B13: BR02 | C13: =IFERROR(VLOOKUP(B13,Branches!A:B, 2, FALSE), B13&"(NOT FOUND)") -> Wuse Branch | D13: 45420 | E13: S004 | F13: =IFERROR(VLOOKUP(E13, Staff!A:B, 2, FALSE), E13&" (NOT FOUND)") -> Ekene Obi | G13: Personal Care | H13: Toothpaste | I13: 3 | K13: 5 | L13: Cash | M13: New | N13: =IF(OR(I13="",J13=""),"",IF(OR(K13="", K13=0), I13*J13, (I13*J13)-(K13/100)*I13*J13)) | O13: NO
A14: 5058 | B14: BR01 | C14: =IFERROR(VLOOKUP(B14,Branches!A:B, 2, FALSE), B14&"(NOT FOUND)") -> Lekki Branch | D14: 45554 | E14: S099 | F14: =IFERROR(VLOOKUP(E14, Staff!A:B, 2, FALSE), E14&" (NOT FOUND)") -> S099 (NOT FOUND) | G14: Home & Kitchen | H14: Blender | I14: 3 | L14: Cash | M14: New | N14: =IF(OR(I14="",J14=""),"",IF(OR(K14="", K14=0), I14*J14, (I14*J14)-(K14/100)*I14*J14)) | O14: NO
A15: 5384 | B15: BR05 | C15: =IFERROR(VLOOKUP(B15,Branches!A:B, 2, FALSE), B15&"(NOT FOUND)") -> Bodija Branch | D15: 45388 | E15: S004 | F15: =IFERROR(VLOOKUP(E15, Staff!A:B, 2, FALSE), E15&" (NOT FOUND)") -> Ekene Obi | G15: Home & Kitchen | H15: Storage Containers | I15: 2 | J15: 17169.84 | K15: 15 | L15: Transfer | M15: Returning | N15: =IF(OR(I15="",J15=""),"",IF(OR(K15="", K15=0), I15*J15, (I15*J15)-(K15/100)*I15*J15)) -> 29188.728 | O15: NO
A16: 5101 | B16: BR05 | C16: =IFERROR(VLOOKUP(B16,Branches!A:B, 2, FALSE), B16&"(NOT FOUND)") -> Bodija Branch | D16: 45549 | E16: S004 | F16: =IFERROR(VLOOKUP(E16, Staff!A:B, 2, FALSE), E16&" (NOT FOUND)") -> Ekene Obi | G16: Personal Care | H16: Deodorant | I16: 3 | J16: 25154.23 | K16: 0 | L16: Transfer | M16: Returning | N16: =IF(OR(I16="",J16=""),"",IF(OR(K16="", K16=0), I16*J16, (I16*J16)-(K16/100)*I16*J16)) -> 75462.69 | O16: NO
A17: 5176 | B17: BR03 | C17: =IFERROR(VLOOKUP(B17,Branches!A:B, 2, FALSE), B17&"(NOT FOUND)") -> GRA Branch | D17: 45373 | E17: S100 | F17: =IFERROR(VLOOKUP(E17, Staff!A:B, 2, FALSE), E17&" (NOT FOUND)") -> S100 (NOT FOUND) | G17: Groceries | H17: Tomato Paste | I17: 1 | K17: 5 | L17: Transfer | M17: Returning | N17: =IF(OR(I17="",J17=""),"",IF(OR(K17="", K17=0), I17*J17, (I17*J17)-(K17/100)*I17*J17)) | O17: NO
A18: 5310 | B18: BR04 | C18: =IFERROR(VLOOKUP(B18,Branches!A:B, 2, FALSE), B18&"(NOT FOUND)") -> Sabon Gari Branch | D18: 45463 | E18: S003 | F18: =IFERROR(VLOOKUP(E18, Staff!A:B, 2, FALSE), E18&" (NOT FOUND)") -> Halima Yusuf | G18: Groceries | H18: Cooking Oil (1L) | K18: 10 | L18: Cash | M18: Returning | N18: =IF(OR(I18="",J18=""),"",IF(OR(K18="", K18=0), I18*J18, (I18*J18)-(K18/100)*I18*J18)) | O18: NO
A19: 5167 | B19: BR03 | C19: =IFERROR(VLOOKUP(B19,Branches!A:B, 2, FALSE), B19&"(NOT FOUND)") -> GRA Branch | D19: 45382 | E19: S007 | F19: =IFERROR(VLOOKUP(E19, Staff!A:B, 2, FALSE), E19&" (NOT FOUND)") -> Kelechi Umeh | G19: Groceries | H19: Spaghetti Pack | I19: 1 | J19: 23400.68 | K19: 10 | L19: Transfer | M19: New | N19: =IF(OR(I19="",J19=""),"",IF(OR(K19="", K19=0), I19*J19, (I19*J19)-(K19/100)*I19*J19)) -> 21060.612 | O19: NO
A20: 5217 | B20: BR05 | C20: =IFERROR(VLOOKUP(B20,Branches!A:B, 2, FALSE), B20&"(NOT FOUND)") -> Bodija Branch | D20: 45561 | E20: S003 | F20: =IFERROR(VLOOKUP(E20, Staff!A:B, 2, FALSE), E20&" (NOT FOUND)") -> Halima Yusuf | G20: Groceries | H20: Tomato Paste | I20: 4 | J20: 5589.59 | L20: Cash | M20: Returning | N20: =IF(OR(I20="",J20=""),"",IF(OR(K20="", K20=0), I20*J20, (I20*J20)-(K20/100)*I20*J20)) -> 22358.36 | O20: YES
A21: 5007 | B21: BR02 | C21: =IFERROR(VLOOKUP(B21,Branches!A:B, 2, FALSE), B21&"(NOT FOUND)") -> Wuse Branch | D21: 45504 | E21: S008 | F21: =IFERROR(VLOOKUP(E21, Staff!A:B, 2, FALSE), E21&" (NOT FOUND)") -> Ronke Bakare | G21: Electronics | H21: Power Bank | I21: 5 | L21: Card | M21: New | N21: =IF(OR(I21="",J21=""),"",IF(OR(K21="", K21=0), I21*J21, (I21*J21)-(K21/100)*I21*J21)) | O21: NO
A22: 5363 | B22: BR05 | C22: =IFERROR(VLOOKUP(B22,Branches!A:B, 2, FALSE), B22&"(NOT FOUND)") -> Bodija Branch | D22: 45553 | E22: S003 | F22: =IFERROR(VLOOKUP(E22, Staff!A:B, 2, FALSE), E22&" (NOT FOUND)") -> Halima Yusuf | G22: Home & Kitchen | H22: Kettle | I22: 4 | J22: 37413.7 | K22: 0 | L22: Cash | M22: Returning | N22: =IF(OR(I22="",J22=""),"",IF(OR(K22="", K22=0), I22*J22, (I22*J22)-(K22/100)*I22*J22)) -> 149654.8
A23: 5271 | B23: BR03 | C23: =IFERROR(VLOOKUP(B23,Branches!A:B, 2, FALSE), B23&"(NOT FOUND)") -> GRA Branch | D23: 45320 | E23: S004 | F23: =IFERROR(VLOOKUP(E23, Staff!A:B, 2, FALSE), E23&" (NOT FOUND)") -> Ekene Obi | G23: Personal Care | H23: Soap Bar | I23: 5 | K23: 10 | L23: Card | M23: Returning | N23: =IF(OR(I23="",J23=""),"",IF(OR(K23="", K23=0), I23*J23, (I23*J23)-(K23/100)*I23*J23)) | O23: YES
A24: 5235 | B24: BR03 | C24: =IFERROR(VLOOKUP(B24,Branches!A:B, 2, FALSE), B24&"(NOT FOUND)") -> GRA Branch | D24: 45380 | E24: S008 | F24: =IFERROR(VLOOKUP(E24, Staff!A:B, 2, FALSE), E24&" (NOT FOUND)") -> Ronke Bakare | G24: Electronics | H24: HDMI Cable | I24: 1 | J24: 42907.41 | K24: 5 | L24: Card | M24: New | N24: =IF(OR(I24="",J24=""),"",IF(OR(K24="", K24=0), I24*J24, (I24*J24)-(K24/100)*I24*J24)) -> 40762.04 | O24: NO
A25: 5116 | B25: BR02 | C25: =IFERROR(VLOOKUP(B25,Branches!A:B, 2, FALSE), B25&"(NOT FOUND)") -> Wuse Branch | D25: 45495 | E25: S006 | F25: =IFERROR(VLOOKUP(E25, Staff!A:B, 2, FALSE), E25&" (NOT FOUND)") -> Ibrahim Sani | G25: Groceries | H25: Cooking Oil (1L) | I25: 1 | K25: 15 | L25: Card | M25: Returning | N25: =IF(OR(I25="",J25=""),"",IF(OR(K25="", K25=0), I25*J25, (I25*J25)-(K25/100)*I25*J25)) | O25: YES
A26: 5353 | B26: BR05 | C26: =IFERROR(VLOOKUP(B26,Branches!A:B, 2, FALSE), B26&"(NOT FOUND)") -> Bodija Branch | D26: 45400 | E26: S008 | F26: =IFERROR(VLOOKUP(E26, Staff!A:B, 2, FALSE), E26&" (NOT FOUND)") -> Ronke Bakare | G26: Home & Kitchen | H26: Cutlery Set | I26: 1 | K26: 10 | L26: Cash | M26: Returning | N26: =IF(OR(I26="",J26=""),"",IF(OR(K26="", K26=0), I26*J26, (I26*J26)-(K26/100)*I26*J26))
A27: 5338 | B27: BR05 | C27: =IFERROR(VLOOKUP(B27,Branches!A:B, 2, FALSE), B27&"(NOT FOUND)") -> Bodija Branch | D27: 45343 | E27: S003 | F27: =IFERROR(VLOOKUP(E27, Staff!A:B, 2, FALSE), E27&" (NOT FOUND)") -> Halima Yusuf | G27: Groceries | H27: Cooking Oil (1L) | K27: 10 | L27: Cash | M27: Returning | N27: =IF(OR(I27="",J27=""),"",IF(OR(K27="", K27=0), I27*J27, (I27*J27)-(K27/100)*I27*J27)) | O27: NO
A28: 5343 | B28: BR02 | C28: =IFERROR(VLOOKUP(B28,Branches!A:B, 2, FALSE), B28&"(NOT FOUND)") -> Wuse Branch | D28: 45557 | E28: S006 | F28: =IFERROR(VLOOKUP(E28, Staff!A:B, 2, FALSE), E28&" (NOT FOUND)") -> Ibrahim Sani | G28: Electronics | H28: HDMI Cable | I28: 3 | L28: Card | M28: New | N28: =IF(OR(I28="",J28=""),"",IF(OR(K28="", K28=0), I28*J28, (I28*J28)-(K28/100)*I28*J28)) | O28: NO
A29: 5372 | B29: BR01 | C29: =IFERROR(VLOOKUP(B29,Branches!A:B, 2, FALSE), B29&"(NOT FOUND)") -> Lekki Branch | D29: 45528 | E29: S008 | F29: =IFERROR(VLOOKUP(E29, Staff!A:B, 2, FALSE), E29&" (NOT FOUND)") -> Ronke Bakare | G29: Home & Kitchen | H29: Kettle | I29: 4 | K29: 5 | L29: Card | M29: Returning | N29: =IF(OR(I29="",J29=""),"",IF(OR(K29="", K29=0), I29*J29, (I29*J29)-(K29/100)*I29*J29)) | O29: YES
A30: 5224 | B30: BR01 | C30: =IFERROR(VLOOKUP(B30,Branches!A:B, 2, FALSE), B30&"(NOT FOUND)") -> Lekki Branch | D30: 45323 | E30: S002 | F30: =IFERROR(VLOOKUP(E30, Staff!A:B, 2, FALSE), E30&" (NOT FOUND)") -> Tobi Adewale | G30: Personal Care | H30: Soap Bar | I30: 1 | J30: 30043.06 | L30: Card | M30: Returning | N30: =IF(OR(I30="",J30=""),"",IF(OR(K30="", K30=0), I30*J30, (I30*J30)-(K30/100)*I30*J30)) -> 30043.06
A31: 5205 | B31: BR04 | C31: =IFERROR(VLOOKUP(B31,Branches!A:B, 2, FALSE), B31&"(NOT FOUND)") -> Sabon Gari Branch | D31: 45313 | E31: S008 | F31: =IFERROR(VLOOKUP(E31, Staff!A:B, 2, FALSE), E31&" (NOT FOUND)") -> Ronke Bakare | G31: Electronics | H31: Power Bank | I31: 3 | J31: 27994.84 | L31: Transfer | M31: Returning | N31: =IF(OR(I31="",J31=""),"",IF(OR(K31="", K31=0), I31*J31, (I31*J31)-(K31/100)*I31*J31)) -> 83984.52 | O31: NO
A32: 5305 | B32: BRXX | C32: =IFERROR(VLOOKUP(B32,Branches!A:B, 2, FALSE), B32&"(NOT FOUND)") -> BRXX(NOT FOUND) | D32: 45401 | E32: S002 | F32: =IFERROR(VLOOKUP(E32, Staff!A:B, 2, FALSE), E32&" (NOT FOUND)") -> Tobi Adewale | G32: Personal Care | H32: Shampoo | I32: 2 | J32: 22968.48 | L32: Transfer | M32: New | N32: =IF(OR(I32="",J32=""),"",IF(OR(K32="", K32=0), I32*J32, (I32*J32)-(K32/100)*I32*J32)) -> 45936.96 | O32: YES
A33: 5210 | B33: BR02 | C33: =IFERROR(VLOOKUP(B33,Branches!A:B, 2, FALSE), B33&"(NOT FOUND)") -> Wuse Branch | D33: 45318 | E33: S001 | F33: =IFERROR(VLOOKUP(E33, Staff!A:B, 2, FALSE), E33&" (NOT FOUND)") -> Chika Nwankwo | G33: Groceries | H33: Sugar (1kg) | I33: 3 | J33: 4354.34 | L33: Transfer | M33: Returning | N33: =IF(OR(I33="",J33=""),"",IF(OR(K33="", K33=0), I33*J33, (I33*J33)-(K33/100)*I33*J33)) -> 13063.02 | O33: NO
A34: 5008 | B34: BR04 | C34: =IFERROR(VLOOKUP(B34,Branches!A:B, 2, FALSE), B34&"(NOT FOUND)") -> Sabon Gari Branch | D34: 45511 | E34: S003 | F34: =IFERROR(VLOOKUP(E34, Staff!A:B, 2, FALSE), E34&" (NOT FOUND)") -> Halima Yusuf | G34: Groceries | H34: Cooking Oil (1L) | I34: 1 | J34: 22080.84 | K34: 0 | L34: Card | M34: New | N34: =IF(OR(I34="",J34=""),"",IF(OR(K34="", K34=0), I34*J34, (I34*J34)-(K34/100)*I34*J34)) -> 22080.84 | O34: NO
A35: 5355 | B35: BR05 | C35: =IFERROR(VLOOKUP(B35,Branches!A:B, 2, FALSE), B35&"(NOT FOUND)") -> Bodija Branch | D35: 45450 | E35: S007 | F35: =IFERROR(VLOOKUP(E35, Staff!A:B, 2, FALSE), E35&" (NOT FOUND)") -> Kelechi Umeh | G35: Personal Care | H35: Body Lotion | I35: 5 | J35: 25569.2 | L35: Cash | M35: Returning | N35: =IF(OR(I35="",J35=""),"",IF(OR(K35="", K35=0), I35*J35, (I35*J35)-(K35/100)*I35*J35)) -> 127846 | O35: YES
A36: 5431 | B36: BR05 | C36: =IFERROR(VLOOKUP(B36,Branches!A:B, 2, FALSE), B36&"(NOT FOUND)") -> Bodija Branch | D36: 45352 | E36: S003 | F36: =IFERROR(VLOOKUP(E36, Staff!A:B, 2, FALSE), E36&" (NOT FOUND)") -> Halima Yusuf | G36: Electronics | H36: HDMI Cable | I36: 2 | J36: 36302.69 | L36: Cash | M36: Returning | N36: =IF(OR(I36="",J36=""),"",IF(OR(K36="", K36=0), I36*J36, (I36*J36)-(K36/100)*I36*J36)) -> 72605.38 | O36: YES
A37: 5373 | B37: BR05 | C37: =IFERROR(VLOOKUP(B37,Branches!A:B, 2, FALSE), B37&"(NOT FOUND)") -> Bodija Branch | D37: 45359 | E37: S002 | F37: =IFERROR(VLOOKUP(E37, Staff!A:B, 2, FALSE), E37&" (NOT FOUND)") -> Tobi Adewale | G37: Personal Care | H37: Deodorant | I37: 1 | J37: 12020.08 | L37: Cash | M37: Returning | N37: =IF(OR(I37="",J37=""),"",IF(OR(K37="", K37=0), I37*J37, (I37*J37)-(K37/100)*I37*J37)) -> 12020.08
A38: 5402 | B38: BR05 | C38: =IFERROR(VLOOKUP(B38,Branches!A:B, 2, FALSE), B38&"(NOT FOUND)") -> Bodija Branch | D38: 45342 | E38: S006 | F38: =IFERROR(VLOOKUP(E38, Staff!A:B, 2, FALSE), E38&" (NOT FOUND)") -> Ibrahim Sani | G38: Groceries | H38: Cooking Oil (1L) | I38: 1 | J38: 30457.19 | L38: Card | M38: New | N38: =IF(OR(I38="",J38=""),"",IF(OR(K38="", K38=0), I38*J38, (I38*J38)-(K38/100)*I38*J38)) -> 30457.19 | O38: NO
A39: 5394 | B39: BR09 | C39: =IFERROR(VLOOKUP(B39,Branches!A:B, 2, FALSE), B39&"(NOT FOUND)") -> BR09(NOT FOUND) | D39: 45325 | E39: S008 | F39: =IFERROR(VLOOKUP(E39, Staff!A:B, 2, FALSE), E39&" (NOT FOUND)") -> Ronke Bakare | G39: Home & Kitchen | H39: Blender | I39: 5 | L39: Cash | M39: Returning | N39: =IF(OR(I39="",J39=""),"",IF(OR(K39="", K39=0), I39*J39, (I39*J39)-(K39/100)*I39*J39)) | O39: YES
A40: 5103 | B40: BR04 | C40: =IFERROR(VLOOKUP(B40,Branches!A:B, 2, FALSE), B40&"(NOT FOUND)") -> Sabon Gari Branch | D40: 45334 | E40: S001 | F40: =IFERROR(VLOOKUP(E40, Staff!A:B, 2, FALSE), E40&" (NOT FOUND)") -> Chika Nwankwo | G40: Groceries | H40: Tomato Paste | L40: Card | M40: Returning | N40: =IF(OR(I40="",J40=""),"",IF(OR(K40="", K40=0), I40*J40, (I40*J40)-(K40/100)*I40*J40)) | O40: NO
...

Sheet Pivot_Summary
B1: TOTAL REVENUE BY BRANCH | M1: BEST AND WORST PERFORMERS
B2: Row Labels | C2: Sum of Total_Sale | M2: Row Labels | N2: Sum of Total_Sale
B3: Bodija Branch | C3: 3652522.9 | M3: Electronics | N3: 5633411.9
B4: GRA Branch | C4: 2623758.5 | M4: Groceries | N4: 4074959.1
B5: Lekki Branch | C5: 4225729.8 | M5: Home & Kitchen | N5: 3034480.5
B6: Sabon Gari Branch | C6: 2742787.6 | M6: Personal Care | N6: 4694020.9
B7: Wuse Branch | C7: 3915249.8 | M7: Grand Total | N7: 17436872
B8: BRXX(NOT FOUND) | C8: 72170.34
B9: BR09(NOT FOUND) | C9: 0
B10: BR12(NOT FOUND) | C10: 204653.5
B11: Grand Total | C11: 17436872
B17: SALES GENERATED BY STAFFS | E17: NEW VS RETURNING CUSTOMER
B18: Row Labels | C18: Sum of Total_Sale | E18: NEW
B19: Chika Nwankwo | C19: 0.11509029 | E19: =AVERAGEIF(Cleaned_Transactions!M:M, "NEW", Cleaned_Transactions!N:N) -> 60077.227
B20: Ekene Obi | C20: 0.14585285 | E20: RETURNING
B21: Funke Ajayi | C21: 0.11734203 | E21: =AVERAGEIF(Cleaned_Transactions!M:M, "RETURNING", Cleaned_Transactions!N:N) -> 65143.982
B22: Halima Yusuf | C22: 0.11757613
B23: Ibrahim Sani | C23: 0.12698752 | N23: Row Labels | O23: Sum of Total_Sale
B24: Kelechi Umeh | C24: 0.10045825 | O24: 1962718.4
B25: Ronke Bakare | C25: 0.15408286 | N25: NO | O25: 7902444.7
B26: Tobi Adewale | C26: 0.1022318 | N26: YES | O26: 7571709.3
B27: S099 (NOT FOUND) | C27: 0.002624992 | N27: Grand Total | O27: 17436872
B28: S100 (NOT FOUND) | C28: 0.014373226
B29: SXXX (NOT FOUND) | C29: 0.003380058
B30: Grand Total | C30: 1

Sheet Branches
A1: branch_code | B1: branch_name | C1: city
A2: BR01 | B2: Lekki Branch | C2: Lagos
A3: BR02 | B3: Wuse Branch | C3: Abuja
A4: BR03 | B4: GRA Branch | C4: Port Harcourt
A5: BR04 | B5: Sabon Gari Branch | C5: Kano
A6: BR05 | B6: Bodija Branch | C6: Ibadan

Sheet Staff
A1: staff_id | B1: staff_name | C1: department
A2: S001 | B2: Chika Nwankwo | C2: Sales
A3: S002 | B3: Tobi Adewale | C3: Sales
A4: S003 | B4: Halima Yusuf | C4: Sales
A5: S004 | B5: Ekene Obi | C5: Sales
A6: S005 | B6: Funke Ajayi | C6: Sales
A7: S006 | B7: Ibrahim Sani | C7: Sales
A8: S007 | B8: Kelechi Umeh | C8: Sales
A9: S008 | B9: Ronke Bakare | C9: Sales
